[2024-10-09 17:12:47,922] {taskinstance.py:1159} INFO - Dependencies all met for <TaskInstance: user_behaviour.download_csv_s3 manual__2024-10-09T17:12:46.926367+00:00 [queued]>
[2024-10-09 17:12:47,934] {taskinstance.py:1159} INFO - Dependencies all met for <TaskInstance: user_behaviour.download_csv_s3 manual__2024-10-09T17:12:46.926367+00:00 [queued]>
[2024-10-09 17:12:47,934] {taskinstance.py:1356} INFO - 
--------------------------------------------------------------------------------
[2024-10-09 17:12:47,934] {taskinstance.py:1357} INFO - Starting attempt 1 of 3
[2024-10-09 17:12:47,934] {taskinstance.py:1358} INFO - 
--------------------------------------------------------------------------------
[2024-10-09 17:12:47,950] {taskinstance.py:1377} INFO - Executing <Task(PythonOperator): download_csv_s3> on 2024-10-09 17:12:46.926367+00:00
[2024-10-09 17:12:47,954] {standard_task_runner.py:52} INFO - Started process 632 to run task
[2024-10-09 17:12:47,957] {standard_task_runner.py:79} INFO - Running: ['***', 'tasks', 'run', 'user_behaviour', 'download_csv_s3', 'manual__2024-10-09T17:12:46.926367+00:00', '--job-id', '6', '--raw', '--subdir', 'DAGS_FOLDER/user_behaviour.py', '--cfg-path', '/tmp/tmpi8dzkjsn', '--error-file', '/tmp/tmp8p9xzqm7']
[2024-10-09 17:12:47,958] {standard_task_runner.py:80} INFO - Job 6: Subtask download_csv_s3
[2024-10-09 17:12:48,012] {task_command.py:370} INFO - Running <TaskInstance: user_behaviour.download_csv_s3 manual__2024-10-09T17:12:46.926367+00:00 [running]> on host acfcc9bdc161
[2024-10-09 17:12:48,085] {taskinstance.py:1571} INFO - Exporting the following env vars:
AIRFLOW_CTX_DAG_EMAIL=***@***.com
AIRFLOW_CTX_DAG_OWNER=***
AIRFLOW_CTX_DAG_ID=user_behaviour
AIRFLOW_CTX_TASK_ID=download_csv_s3
AIRFLOW_CTX_EXECUTION_DATE=2024-10-09T17:12:46.926367+00:00
AIRFLOW_CTX_TRY_NUMBER=1
AIRFLOW_CTX_DAG_RUN_ID=manual__2024-10-09T17:12:46.926367+00:00
[2024-10-09 17:12:48,086] {taskinstance.py:1889} ERROR - Task failed with exception
Traceback (most recent call last):
  File "/home/airflow/.local/lib/python3.7/site-packages/airflow/operators/python.py", line 171, in execute
    return_value = self.execute_callable()
  File "/home/airflow/.local/lib/python3.7/site-packages/airflow/operators/python.py", line 189, in execute_callable
    return self.python_callable(*self.op_args, **self.op_kwargs)
TypeError: download_csv_s3_func() missing 1 required positional argument: 'bucket_name'
[2024-10-09 17:12:48,094] {taskinstance.py:1400} INFO - Marking task as UP_FOR_RETRY. dag_id=user_behaviour, task_id=download_csv_s3, execution_date=20241009T171246, start_date=20241009T171247, end_date=20241009T171248
[2024-10-09 17:12:48,105] {standard_task_runner.py:97} ERROR - Failed to execute job 6 for task download_csv_s3 (download_csv_s3_func() missing 1 required positional argument: 'bucket_name'; 632)
[2024-10-09 17:12:48,131] {local_task_job.py:156} INFO - Task exited with return code 1
[2024-10-09 17:12:48,187] {local_task_job.py:273} INFO - 0 downstream tasks scheduled from follow-on schedule check
