[2024-10-08 17:55:17,464] {taskinstance.py:1159} INFO - Dependencies all met for <TaskInstance: user_behaviour.dbt_test scheduled__2024-10-07T00:00:00+00:00 [queued]>
[2024-10-08 17:55:17,481] {taskinstance.py:1159} INFO - Dependencies all met for <TaskInstance: user_behaviour.dbt_test scheduled__2024-10-07T00:00:00+00:00 [queued]>
[2024-10-08 17:55:17,481] {taskinstance.py:1356} INFO - 
--------------------------------------------------------------------------------
[2024-10-08 17:55:17,481] {taskinstance.py:1357} INFO - Starting attempt 2 of 3
[2024-10-08 17:55:17,481] {taskinstance.py:1358} INFO - 
--------------------------------------------------------------------------------
[2024-10-08 17:55:17,496] {taskinstance.py:1377} INFO - Executing <Task(BashOperator): dbt_test> on 2024-10-07 00:00:00+00:00
[2024-10-08 17:55:17,499] {standard_task_runner.py:52} INFO - Started process 389 to run task
[2024-10-08 17:55:17,502] {standard_task_runner.py:79} INFO - Running: ['***', 'tasks', 'run', 'user_behaviour', 'dbt_test', 'scheduled__2024-10-07T00:00:00+00:00', '--job-id', '4', '--raw', '--subdir', 'DAGS_FOLDER/user_behaviour.py', '--cfg-path', '/tmp/tmpfoks6piz', '--error-file', '/tmp/tmpe2y5la82']
[2024-10-08 17:55:17,503] {standard_task_runner.py:80} INFO - Job 4: Subtask dbt_test
[2024-10-08 17:55:17,519] {logging_mixin.py:115} WARNING - /home/***/.local/lib/python3.7/site-packages/***/configuration.py:525 DeprecationWarning: The sql_alchemy_conn option in [core] has been moved to the sql_alchemy_conn option in [database] - the old setting has been used, but please update your config.
[2024-10-08 17:55:17,556] {task_command.py:370} INFO - Running <TaskInstance: user_behaviour.dbt_test scheduled__2024-10-07T00:00:00+00:00 [running]> on host e289ee31b3ca
[2024-10-08 17:55:17,624] {taskinstance.py:1571} INFO - Exporting the following env vars:
AIRFLOW_CTX_DAG_EMAIL=***@***.com
AIRFLOW_CTX_DAG_OWNER=***
AIRFLOW_CTX_DAG_ID=user_behaviour
AIRFLOW_CTX_TASK_ID=dbt_test
AIRFLOW_CTX_EXECUTION_DATE=2024-10-07T00:00:00+00:00
AIRFLOW_CTX_TRY_NUMBER=2
AIRFLOW_CTX_DAG_RUN_ID=scheduled__2024-10-07T00:00:00+00:00
[2024-10-08 17:55:17,625] {subprocess.py:62} INFO - Tmp dir root location: 
 /tmp
[2024-10-08 17:55:17,625] {subprocess.py:74} INFO - Running command: ['bash', '-c', 'cd /opt/***/dbt/data_pipeline && dbt test']
[2024-10-08 17:55:17,633] {subprocess.py:85} INFO - Output:
[2024-10-08 17:55:19,889] {subprocess.py:92} INFO - Running with dbt=1.0.0-b2
[2024-10-08 17:55:19,892] {subprocess.py:92} INFO - Encountered an error while reading the project:
[2024-10-08 17:55:19,892] {subprocess.py:92} INFO -   ERROR: Runtime Error
[2024-10-08 17:55:19,892] {subprocess.py:92} INFO -   Could not find profile named 'data_pipeline'
[2024-10-08 17:55:19,899] {subprocess.py:92} INFO - Encountered an error:
[2024-10-08 17:55:19,899] {subprocess.py:92} INFO - Runtime Error
[2024-10-08 17:55:19,899] {subprocess.py:92} INFO -   Could not run dbt
[2024-10-08 17:55:19,996] {subprocess.py:96} INFO - Command exited with return code 2
[2024-10-08 17:55:20,012] {taskinstance.py:1889} ERROR - Task failed with exception
Traceback (most recent call last):
  File "/home/airflow/.local/lib/python3.7/site-packages/airflow/operators/bash.py", line 195, in execute
    f'Bash command failed. The command returned a non-zero exit code {result.exit_code}.'
airflow.exceptions.AirflowException: Bash command failed. The command returned a non-zero exit code 2.
[2024-10-08 17:55:20,016] {taskinstance.py:1400} INFO - Marking task as UP_FOR_RETRY. dag_id=user_behaviour, task_id=dbt_test, execution_date=20241007T000000, start_date=20241008T175517, end_date=20241008T175520
[2024-10-08 17:55:20,029] {standard_task_runner.py:97} ERROR - Failed to execute job 4 for task dbt_test (Bash command failed. The command returned a non-zero exit code 2.; 389)
[2024-10-08 17:55:20,043] {local_task_job.py:156} INFO - Task exited with return code 1
[2024-10-08 17:55:20,090] {local_task_job.py:273} INFO - 0 downstream tasks scheduled from follow-on schedule check
