[2024-10-11T14:01:40.077+0000] {local_task_job_runner.py:120} INFO - ::group::Pre task execution logs
[2024-10-11T14:01:40.093+0000] {taskinstance.py:2076} INFO - Dependencies all met for dep_context=non-requeueable deps ti=<TaskInstance: user_behaviour.load_s3_to_snowflake manual__2024-10-11T14:01:37.760975+00:00 [queued]>
[2024-10-11T14:01:40.102+0000] {taskinstance.py:2076} INFO - Dependencies all met for dep_context=requeueable deps ti=<TaskInstance: user_behaviour.load_s3_to_snowflake manual__2024-10-11T14:01:37.760975+00:00 [queued]>
[2024-10-11T14:01:40.102+0000] {taskinstance.py:2306} INFO - Starting attempt 1 of 1
[2024-10-11T14:01:40.116+0000] {taskinstance.py:2330} INFO - Executing <Task(SnowflakeOperator): load_s3_to_snowflake> on 2024-10-11 14:01:37.760975+00:00
[2024-10-11T14:01:40.124+0000] {warnings.py:112} WARNING - /home/***/.local/lib/python3.12/site-packages/***/task/task_runner/standard_task_runner.py:61: DeprecationWarning: This process (pid=553) is multi-threaded, use of fork() may lead to deadlocks in the child.
  pid = os.fork()

[2024-10-11T14:01:40.127+0000] {standard_task_runner.py:63} INFO - Started process 555 to run task
[2024-10-11T14:01:40.127+0000] {standard_task_runner.py:90} INFO - Running: ['***', 'tasks', 'run', 'user_behaviour', 'load_s3_to_snowflake', 'manual__2024-10-11T14:01:37.760975+00:00', '--job-id', '8', '--raw', '--subdir', 'DAGS_FOLDER/user_behaviour.py', '--cfg-path', '/tmp/tmpp5c_n8kp']
[2024-10-11T14:01:40.130+0000] {standard_task_runner.py:91} INFO - Job 8: Subtask load_s3_to_snowflake
[2024-10-11T14:01:40.182+0000] {task_command.py:426} INFO - Running <TaskInstance: user_behaviour.load_s3_to_snowflake manual__2024-10-11T14:01:37.760975+00:00 [running]> on host 7326b1a9492c
[2024-10-11T14:01:40.270+0000] {taskinstance.py:2648} INFO - Exporting env vars: AIRFLOW_CTX_DAG_OWNER='***' AIRFLOW_CTX_DAG_ID='user_behaviour' AIRFLOW_CTX_TASK_ID='load_s3_to_snowflake' AIRFLOW_CTX_EXECUTION_DATE='2024-10-11T14:01:37.760975+00:00' AIRFLOW_CTX_TRY_NUMBER='1' AIRFLOW_CTX_DAG_RUN_ID='manual__2024-10-11T14:01:37.760975+00:00'
[2024-10-11T14:01:40.272+0000] {taskinstance.py:430} INFO - ::endgroup::
[2024-10-11T14:01:40.287+0000] {sql.py:276} INFO - Executing:  
        COPY INTO DBT_DB.DBT_SCHEMA_RAW_LAYER.customers 
        FROM '@DBT_DB.DBT_SCHEMA_RAW_LAYER.staging_csv_files/customers.csv'
        FILE_FORMAT = (TYPE = 'CSV' FIELD_OPTIONALLY_ENCLOSED_BY = '"' SKIP_HEADER = 1) 
        PATTERN = '.*.csv';
        
[2024-10-11T14:01:40.288+0000] {crypto.py:82} WARNING - empty cryptography key - values will not be stored encrypted.
[2024-10-11T14:01:40.289+0000] {base.py:84} INFO - Using connection ID 'snowflake_conn' for task execution.
[2024-10-11T14:01:40.292+0000] {base.py:84} INFO - Using connection ID 'snowflake_conn' for task execution.
[2024-10-11T14:01:40.293+0000] {connection.py:399} INFO - Snowflake Connector for Python Version: 3.10.1, Python Version: 3.12.4, Platform: Linux-5.15.153.1-microsoft-standard-WSL2-x86_64-with-glibc2.36
[2024-10-11T14:01:40.294+0000] {connection.py:1239} INFO - This connection is in OCSP Fail Open Mode. TLS Certificates would be checked for validity and revocation status. Any other Certificate Revocation related exceptions or OCSP Responder failures would be disregarded in favor of connectivity.
[2024-10-11T14:01:41.936+0000] {taskinstance.py:441} INFO - ::group::Post task execution logs
[2024-10-11T14:01:41.936+0000] {taskinstance.py:2905} ERROR - Task failed with exception
Traceback (most recent call last):
  File "/home/airflow/.local/lib/python3.12/site-packages/airflow/models/taskinstance.py", line 465, in _execute_task
    result = _execute_callable(context=context, **execute_callable_kwargs)
             ^^^^^^^^^^^^^^^^^^^^^^^^^^^^^^^^^^^^^^^^^^^^^^^^^^^^^^^^^^^^^
  File "/home/airflow/.local/lib/python3.12/site-packages/airflow/models/taskinstance.py", line 432, in _execute_callable
    return execute_callable(context=context, **execute_callable_kwargs)
           ^^^^^^^^^^^^^^^^^^^^^^^^^^^^^^^^^^^^^^^^^^^^^^^^^^^^^^^^^^^^
  File "/home/airflow/.local/lib/python3.12/site-packages/airflow/models/baseoperator.py", line 401, in wrapper
    return func(self, *args, **kwargs)
           ^^^^^^^^^^^^^^^^^^^^^^^^^^^
  File "/home/airflow/.local/lib/python3.12/site-packages/airflow/providers/common/sql/operators/sql.py", line 282, in execute
    output = hook.run(
             ^^^^^^^^^
  File "/home/airflow/.local/lib/python3.12/site-packages/airflow/providers/snowflake/hooks/snowflake.py", line 392, in run
    with closing(self.get_conn()) as conn:
                 ^^^^^^^^^^^^^^^
  File "/home/airflow/.local/lib/python3.12/site-packages/airflow/providers/snowflake/hooks/snowflake.py", line 290, in get_conn
    conn = connector.connect(**conn_config)
           ^^^^^^^^^^^^^^^^^^^^^^^^^^^^^^^^
  File "/home/airflow/.local/lib/python3.12/site-packages/snowflake/connector/__init__.py", line 55, in Connect
    return SnowflakeConnection(**kwargs)
           ^^^^^^^^^^^^^^^^^^^^^^^^^^^^^
  File "/home/airflow/.local/lib/python3.12/site-packages/snowflake/connector/connection.py", line 442, in __init__
    self.connect(**kwargs)
  File "/home/airflow/.local/lib/python3.12/site-packages/snowflake/connector/connection.py", line 745, in connect
    self.__open_connection()
  File "/home/airflow/.local/lib/python3.12/site-packages/snowflake/connector/connection.py", line 1073, in __open_connection
    self.authenticate_with_retry(self.auth_class)
  File "/home/airflow/.local/lib/python3.12/site-packages/snowflake/connector/connection.py", line 1345, in authenticate_with_retry
    self._authenticate(auth_instance)
  File "/home/airflow/.local/lib/python3.12/site-packages/snowflake/connector/connection.py", line 1373, in _authenticate
    auth.authenticate(
  File "/home/airflow/.local/lib/python3.12/site-packages/snowflake/connector/auth/_auth.py", line 250, in authenticate
    ret = self._rest._post_request(
          ^^^^^^^^^^^^^^^^^^^^^^^^^
  File "/home/airflow/.local/lib/python3.12/site-packages/snowflake/connector/network.py", line 734, in _post_request
    ret = self.fetch(
          ^^^^^^^^^^^
  File "/home/airflow/.local/lib/python3.12/site-packages/snowflake/connector/network.py", line 843, in fetch
    ret = self._request_exec_wrapper(
          ^^^^^^^^^^^^^^^^^^^^^^^^^^^
  File "/home/airflow/.local/lib/python3.12/site-packages/snowflake/connector/network.py", line 979, in _request_exec_wrapper
    raise e
  File "/home/airflow/.local/lib/python3.12/site-packages/snowflake/connector/network.py", line 884, in _request_exec_wrapper
    return_object = self._request_exec(
                    ^^^^^^^^^^^^^^^^^^^
  File "/home/airflow/.local/lib/python3.12/site-packages/snowflake/connector/network.py", line 1193, in _request_exec
    raise err
  File "/home/airflow/.local/lib/python3.12/site-packages/snowflake/connector/network.py", line 1135, in _request_exec
    raise_failed_request_error(
  File "/home/airflow/.local/lib/python3.12/site-packages/snowflake/connector/network.py", line 238, in raise_failed_request_error
    Error.errorhandler_wrapper(
  File "/home/airflow/.local/lib/python3.12/site-packages/snowflake/connector/errors.py", line 290, in errorhandler_wrapper
    handed_over = Error.hand_to_other_handler(
                  ^^^^^^^^^^^^^^^^^^^^^^^^^^^^
  File "/home/airflow/.local/lib/python3.12/site-packages/snowflake/connector/errors.py", line 348, in hand_to_other_handler
    connection.errorhandler(connection, cursor, error_class, error_value)
  File "/home/airflow/.local/lib/python3.12/site-packages/snowflake/connector/errors.py", line 221, in default_errorhandler
    raise error_class(
snowflake.connector.errors.InterfaceError: 250003 (08001): None: 404 Not Found: post https://jr51262.eu-central-1.snowflakecomputing.com:443/session/v1/login-request?request_id=5879772a-bf04-4a7c-8d8b-24f990591aff&databaseName=dbt_db&schemaName=dbt_schema_raw_layer&warehouse=dbt_wh&roleName=dbt_role&request_guid=1622100d-92c1-4e60-84e6-1a055703d831
[2024-10-11T14:01:41.951+0000] {taskinstance.py:1206} INFO - Marking task as FAILED. dag_id=user_behaviour, task_id=load_s3_to_snowflake, run_id=manual__2024-10-11T14:01:37.760975+00:00, execution_date=20241011T140137, start_date=20241011T140140, end_date=20241011T140141
[2024-10-11T14:01:41.967+0000] {standard_task_runner.py:110} ERROR - Failed to execute job 8 for task load_s3_to_snowflake (250003 (08001): None: 404 Not Found: post https://jr51262.eu-central-1.snowflakecomputing.com:443/session/v1/login-request?request_id=5879772a-bf04-4a7c-8d8b-24f990591aff&databaseName=dbt_db&schemaName=dbt_schema_raw_layer&warehouse=dbt_wh&roleName=dbt_role&request_guid=1622100d-92c1-4e60-84e6-1a055703d831; 555)
[2024-10-11T14:01:41.992+0000] {local_task_job_runner.py:240} INFO - Task exited with return code 1
[2024-10-11T14:01:42.005+0000] {local_task_job_runner.py:222} INFO - ::endgroup::
