[2024-10-11T15:25:57.138+0000] {local_task_job_runner.py:120} INFO - ::group::Pre task execution logs
[2024-10-11T15:25:57.162+0000] {taskinstance.py:2076} INFO - Dependencies all met for dep_context=non-requeueable deps ti=<TaskInstance: user_behaviour.dbt_snapshot manual__2024-10-11T15:24:43.455907+00:00 [queued]>
[2024-10-11T15:25:57.171+0000] {taskinstance.py:2076} INFO - Dependencies all met for dep_context=requeueable deps ti=<TaskInstance: user_behaviour.dbt_snapshot manual__2024-10-11T15:24:43.455907+00:00 [queued]>
[2024-10-11T15:25:57.172+0000] {taskinstance.py:2306} INFO - Starting attempt 2 of 2
[2024-10-11T15:25:57.187+0000] {taskinstance.py:2330} INFO - Executing <Task(BashOperator): dbt_snapshot> on 2024-10-11 15:24:43.455907+00:00
[2024-10-11T15:25:57.193+0000] {warnings.py:112} WARNING - /home/***/.local/lib/python3.12/site-packages/***/task/task_runner/standard_task_runner.py:61: DeprecationWarning: This process (pid=1097) is multi-threaded, use of fork() may lead to deadlocks in the child.
  pid = os.fork()

[2024-10-11T15:25:57.195+0000] {standard_task_runner.py:63} INFO - Started process 1099 to run task
[2024-10-11T15:25:57.194+0000] {standard_task_runner.py:90} INFO - Running: ['***', 'tasks', 'run', 'user_behaviour', 'dbt_snapshot', 'manual__2024-10-11T15:24:43.455907+00:00', '--job-id', '40', '--raw', '--subdir', 'DAGS_FOLDER/user_behaviour.py', '--cfg-path', '/tmp/tmps86h2ar8']
[2024-10-11T15:25:57.197+0000] {standard_task_runner.py:91} INFO - Job 40: Subtask dbt_snapshot
[2024-10-11T15:25:57.243+0000] {task_command.py:426} INFO - Running <TaskInstance: user_behaviour.dbt_snapshot manual__2024-10-11T15:24:43.455907+00:00 [running]> on host 40ee99ca9dd7
[2024-10-11T15:25:57.326+0000] {taskinstance.py:2648} INFO - Exporting env vars: AIRFLOW_CTX_DAG_EMAIL='***@***.com' AIRFLOW_CTX_DAG_OWNER='***' AIRFLOW_CTX_DAG_ID='user_behaviour' AIRFLOW_CTX_TASK_ID='dbt_snapshot' AIRFLOW_CTX_EXECUTION_DATE='2024-10-11T15:24:43.455907+00:00' AIRFLOW_CTX_TRY_NUMBER='2' AIRFLOW_CTX_DAG_RUN_ID='manual__2024-10-11T15:24:43.455907+00:00'
[2024-10-11T15:25:57.327+0000] {taskinstance.py:430} INFO - ::endgroup::
[2024-10-11T15:25:57.340+0000] {subprocess.py:63} INFO - Tmp dir root location: /tmp
[2024-10-11T15:25:57.341+0000] {subprocess.py:75} INFO - Running command: ['/usr/bin/bash', '-c', 'dbt snapshot --project-dir /opt/***/dbt/data_pipeline --profiles-dir /opt/***/dbt/data_pipeline/profiles/']
[2024-10-11T15:25:57.351+0000] {subprocess.py:86} INFO - Output:
[2024-10-11T15:25:59.713+0000] {subprocess.py:93} INFO - Usage: dbt snapshot [OPTIONS]
[2024-10-11T15:25:59.714+0000] {subprocess.py:93} INFO - Try 'dbt snapshot -h' for help.
[2024-10-11T15:25:59.714+0000] {subprocess.py:93} INFO - 
[2024-10-11T15:25:59.714+0000] {subprocess.py:93} INFO - Error: Invalid value for '--profiles-dir': Path '/opt/***/dbt/data_pipeline/profiles/' does not exist.
[2024-10-11T15:25:59.944+0000] {subprocess.py:97} INFO - Command exited with return code 2
[2024-10-11T15:25:59.945+0000] {taskinstance.py:441} INFO - ::group::Post task execution logs
[2024-10-11T15:25:59.957+0000] {taskinstance.py:2905} ERROR - Task failed with exception
Traceback (most recent call last):
  File "/home/airflow/.local/lib/python3.12/site-packages/airflow/models/taskinstance.py", line 465, in _execute_task
    result = _execute_callable(context=context, **execute_callable_kwargs)
             ^^^^^^^^^^^^^^^^^^^^^^^^^^^^^^^^^^^^^^^^^^^^^^^^^^^^^^^^^^^^^
  File "/home/airflow/.local/lib/python3.12/site-packages/airflow/models/taskinstance.py", line 432, in _execute_callable
    return execute_callable(context=context, **execute_callable_kwargs)
           ^^^^^^^^^^^^^^^^^^^^^^^^^^^^^^^^^^^^^^^^^^^^^^^^^^^^^^^^^^^^
  File "/home/airflow/.local/lib/python3.12/site-packages/airflow/models/baseoperator.py", line 401, in wrapper
    return func(self, *args, **kwargs)
           ^^^^^^^^^^^^^^^^^^^^^^^^^^^
  File "/home/airflow/.local/lib/python3.12/site-packages/airflow/operators/bash.py", line 243, in execute
    raise AirflowException(
airflow.exceptions.AirflowException: Bash command failed. The command returned a non-zero exit code 2.
[2024-10-11T15:25:59.961+0000] {taskinstance.py:1206} INFO - Marking task as FAILED. dag_id=user_behaviour, task_id=dbt_snapshot, run_id=manual__2024-10-11T15:24:43.455907+00:00, execution_date=20241011T152443, start_date=20241011T152557, end_date=20241011T152559
[2024-10-11T15:25:59.976+0000] {standard_task_runner.py:110} ERROR - Failed to execute job 40 for task dbt_snapshot (Bash command failed. The command returned a non-zero exit code 2.; 1099)
[2024-10-11T15:26:00.022+0000] {local_task_job_runner.py:240} INFO - Task exited with return code 1
[2024-10-11T15:26:00.048+0000] {taskinstance.py:3503} INFO - 0 downstream tasks scheduled from follow-on schedule check
[2024-10-11T15:26:00.053+0000] {local_task_job_runner.py:222} INFO - ::endgroup::
